Workbook

Sheet Whole_Data_RNAseq
A1: Wave | B1: Sample Name | C1: Code Axiom | D1: Genetic Code | E1: Fecha de extraccion | F1: Nucleic Acid ID | G1: Concentration(ng/ul) | H1: Volume(ul) | I1: Total amount(ug) | J1: Integrity value | K1: Sample QC Results | L1: Sample QC Memo | M1: Recommendation | N1: Note | O1: Genotyping data | P1: Exclude from the study | Q1: SEX | R1: Edad | S1: Aff status BD | T1: BD subtipo | U1: Aff status SUI Attem | V1: Notas | W1: MDS | X1: Lithium>1yr | Y1: Lithium<1yr | Z1: Event (LUNKDBECK32) | AA1: Phenotyping date | AB1: Extraction date | AC1: Medicado? (si/no) | AD1: Num medicaciones | AE1: Alguna es mood stabilizer? (si/no)
A2: WAVE-2 | B2: CSICR_0001 | C2: CSI_0001 | D2: CSI_1 | E2: #N/A | F2: FKRN240159961-1A | G2: 110 | H2: 9.1 | I2: 1.001 | J2: 9.8 | K2: Pass | L2: - | M2: Proceed | O2: Genotyped | P2: INCLUDE | Q2: 2 | R2: 55 | S2: 1 | U2: 1 | W2: EUR | X2: #N/A | Y2: #N/A | AB2: 44610
A3: WAVE-2 | B3: CSICR_0008 | C3: CSI_0008 | D3: CSI_8 | E3: #N/A | F3: FKRN240159962-1A | G3: 81 | H3: 8.1 | I3: 0.6561 | J3: 8.6 | K3: Pass | L3: - | M3: Proceed | O3: Genotyped | P3: INCLUDE | Q3: 2 | R3: 51 | S3: 1 | U3: 1 | W3: EUR | X3: #N/A | Y3: #N/A | AB3: 44816
A4: WAVE-2 | B4: CSICR_0011 | C4: CSI_0011 | D4: CSI_11 | E4: #N/A | F4: FKRN240159963-1A | G4: 130 | H4: 8.5 | I4: 1.105 | J4: 9 | K4: Pass | L4: - | M4: Proceed | O4: Genotyped | P4: INCLUDE | Q4: 1 | R4: 46 | S4: 1 | U4: 1 | W4: EUR | X4: #N/A | Y4: #N/A | AB4: 44818
A5: WAVE-2 | B5: CSICR_0012 | C5: CSI_0012 | D5: CSI_12 | E5: #N/A | F5: FKRN240159964-1A | G5: 121 | H5: 9.2 | I5: 1.1132 | J5: 9.8 | K5: Pass | L5: - | M5: Proceed | O5: Genotyped | P5: INCLUDE | Q5: 1 | R5: 57 | S5: 1 | U5: 1 | W5: EUR | X5: #N/A | Y5: #N/A | AB5: 44818
A6: WAVE-2 | B6: CSICR_0013 | C6: CSI_0013 | D6: CSI_13 | E6: #N/A | F6: FKRN240159965-1A | G6: 142 | H6: 8 | I6: 1.136 | J6: 9.8 | K6: Pass | L6: - | M6: Proceed | O6: Genotyped | P6: INCLUDE | Q6: 2 | R6: 48 | S6: 1 | U6: 1 | W6: EUR | X6: #N/A | Y6: #N/A | AB6: 44818
A7: WAVE-2 | B7: CSICR_0015 | C7: CSI_0015 | D7: CSI_15 | E7: #N/A | F7: FKRN240159966-1A | G7: 97 | H7: 8.3 | I7: 0.8051 | J7: 9 | K7: Pass | L7: - | M7: Proceed | O7: Genotyped | P7: INCLUDE | Q7: 2 | R7: 57 | S7: 1 | U7: 1 | W7: EUR | X7: #N/A | Y7: #N/A | AB7: 44823
A8: WAVE-2 | B8: CSICR_0017 | C8: CSI_0017 | D8: CSI_17 | E8: #N/A | F8: FKRN240159967-1A | G8: 62 | H8: 8.3 | I8: 0.5146 | J8: 9.8 | K8: Pass | L8: - | M8: Proceed | O8: Genotyped | P8: INCLUDE | Q8: 2 | R8: 53 | S8: 1 | U8: 1 | W8: EUR | X8: #N/A | Y8: #N/A | AB8: 44830
A9: WAVE-R | B9: CSICR_0018 | C9: CSI_0018 | D9: CSI_18 | E9: #N/A | F9: FKRN250010444-1A | G9: 32 | H9: 20 | I9: 0.64 | J9: 9.6 | K9: Pass | L9: - | M9: Pass | O9: Genotyped | P9: INCLUDE | Q9: 2 | R9: 59 | S9: 1 | U9: 1 | W9: EUR | X9: #N/A | Y9: #N/A | AB9: 44830
A10: WAVE-3 | B10: CSICR_0026 | C10: CSI_0026 | D10: CSI_26 | E10: #N/A | F10: FKRN240343450-1A | G10: 82 | H10: 11 | I10: 0.902 | J10: 9.4 | K10: Pass | L10: Slightly impure | M10: Proceed | O10: Genotyped | P10: INCLUDE | Q10: 2 | R10: 63 | S10: 1 | U10: 1 | W10: EUR | X10: #N/A | Y10: #N/A | AB10: 44832
A11: WAVE-3 | B11: CSICR_0030 | C11: CSI_0030 | D11: CSI_30 | E11: #N/A | F11: FKRN240343451-1A | G11: 138 | H11: 11 | I11: 1.518 | J11: 9.2 | K11: Pass | L11: Slightly impure | M11: Proceed | O11: Genotyped | P11: INCLUDE | Q11: 2 | R11: 49 | S11: 1 | U11: 1 | W11: EUR | X11: #N/A | Y11: #N/A | AB11: 44844
A12: WAVE-3 | B12: CSICR_0031 | C12: CSI_0031 | D12: CSI_31 | E12: #N/A | F12: FKRN240343452-1A | G12: 129 | H12: 11 | I12: 1.419 | J12: 9.5 | K12: Pass | L12: Slightly impure | M12: Proceed | O12: Genotyped | P12: INCLUDE | Q12: 1 | R12: 50 | S12: 1 | U12: 1 | W12: EUR | X12: #N/A | Y12: #N/A | AB12: 44844
A13: WAVE-3 | B13: CSICR_0033 | C13: CSI_0033 | D13: CSI_33 | E13: #N/A | F13: FKRN240343453-1A | G13: 105 | H13: 11 | I13: 1.155 | J13: 9.8 | K13: Pass | L13: Slightly impure | M13: Proceed | O13: Genotyped | P13: INCLUDE | Q13: 2 | R13: 63 | S13: 1 | U13: 1 | W13: EUR | X13: #N/A | Y13: #N/A | AB13: 44858
... A48: WAVE-3 | B48: CSICR_0102 | C48: CSI_0102 | D48: CSI_102 | E48: #N/A | F48: FKRN240343489-1A | G48: 115 | H48: 10 | I48: 1.15 | J48: 9.5 | K48: Pass | L48: - | M48: Proceed | O48: Genotyped | P48: INCLUDE | Q48: 1 | R48: 41 | S48: 1 | U48: 1 | W48: EUR | X48: #N/A | Y48: #N/A | AB48: 45112
A49: WAVE-F | B49: CSICR_0106 | C49: CSI_0106 | D49: CSI_106 | E49: #N/A | F49: FKRN250020215-1A | G49: 104 | H49: 14 | I49: 1.456 | J49: 9.9 | K49: Pass | L49: - | M49: Pass | O49: Genotyped | P49: INCLUDE | Q49: 1 | R49: 45 | S49: 2 | T49: BD II | U49: 2 | W49: EUR | X49: #N/A | Y49: #N/A | AB49: 45182
A50: WAVE-3 | B50: CSICR_0111 | C50: CSI_0111 | D50: CSI_111 | E50: #N/A | F50: FKRN240343490-1A | G50: 97 | H50: 11 | I50: 1.067 | J50: 9.2 | K50: Pass | L50: - | M50: Proceed | O50: Genotyped | P50: INCLUDE | Q50: 1 | R50: 24 | S50: 1 | U50: 1 | W50: EUR | X50: #N/A | Y50: #N/A | AB50: 45182
A51: WAVE-3 | B51: CSICR_0112 | C51: CSI_0112 | D51: CSI_112 | E51: #N/A | F51: FKRN240343491-1A | G51: 65 | H51: 11 | I51: 0.715 | J51: 9.5 | K51: Pass | L51: - | M51: Proceed | O51: Genotyped | P51: INCLUDE | Q51: 1 | R51: 47 | S51: 1 | U51: 1 | W51: EUR | X51: #N/A | Y51: #N/A | AB51: 45182
A52: WAVE-3 | B52: CSICR_0113 | C52: CSI_0113 | D52: CSI_113 | E52: #N/A | F52: FKRN240343492-1A | G52: 85 | H52: 8 | I52: 0.68 | J52: 8.4 | K52: Pass | L52: - | M52: Proceed | O52: Genotyped | P52: INCLUDE | Q52: 2 | R52: 27 | S52: 1 | U52: 1 | W52: EUR | X52: #N/A | Y52: #N/A | AB52: 45188
A53: WAVE-3 | B53: CSICR_0121 | C53: CSI_0121 | D53: CSI_121 | E53: #N/A | F53: FKRN240343493-1A | G53: 94 | H53: 11 | I53: 1.034 | J53: 9.5 | K53: Pass | L53: - | M53: Proceed | O53: Genotyped | P53: INCLUDE | Q53: 2 | R53: 30 | S53: 1 | U53: 1 | W53: EUR | X53: #N/A | Y53: #N/A | AB53: 45188
A54: WAVE-3 | B54: CSICR_0122 | C54: CSI_0122 | D54: CSI_122 | E54: #N/A | F54: FKRN240343494-1A | G54: 80 | H54: 11 | I54: 0.88 | J54: 9.3 | K54: Pass | L54: - | M54: Proceed | O54: Genotyped | P54: INCLUDE | Q54: 1 | R54: 18 | S54: 1 | U54: 1 | W54: EUR | X54: #N/A | Y54: #N/A | AB54: 45194
A55: WAVE-3 | B55: CSICR_0123 | C55: CSI_0123 | D55: CSI_123 | E55: #N/A | F55: FKRN240343495-1A | G55: 94 | H55: 11 | I55: 1.034 | J55: 8.7 | K55: Pass | L55: - | M55: Proceed | O55: Genotyped | P55: INCLUDE | Q55: 2 | R55: 50 | S55: 1 | U55: 1 | W55: EUR | X55: #N/A | Y55: #N/A | AB55: 45196
A56: WAVE-3 | B56: CSICR_0129 | C56: CSI_0129 | D56: CSI_129 | E56: #N/A | F56: FKRN240343496-1A | G56: 145 | H56: 10 | I56: 1.45 | J56: 9.6 | K56: Pass | L56: - | M56: Proceed | O56: Genotyped | P56: INCLUDE | Q56: 2 | R56: 22 | S56: 1 | U56: 1 | W56: EUR | X56: #N/A | Y56: #N/A | AB56: 45196
A57: WAVE-3 | B57: CSICR_0133 | C57: CSI_0133 | D57: CSI_133 | E57: #N/A | F57: FKRN240343497-1A | G57: 113 | H57: 9.7 | I57: 1.0961 | J57: 7.2 | K57: Pass | L57: Slightly impure | M57: Proceed | O57: Genotyped | P57: INCLUDE | Q57: 1 | R57: 51 | S57: 1 | U57: 1 | W57: EUR | X57: #N/A | Y57: #N/A | AB57: 45196
A58: WAVE-3 | B58: CSICR_0134 | C58: CSI_0134 | D58: CSI_134 | E58: #N/A | F58: FKRN240343498-1A | G58: 108 | H58: 9.8 | I58: 1.0584 | J58: 9.2 | K58: Pass | L58: Slightly impure | M58: Proceed | O58: Genotyped | P58: INCLUDE | Q58: 2 | R58: 21 | S58: 1 | U58: 1 | W58: EUR | X58: #N/A | Y58: #N/A | AB58: 45397
A59: WAVE-3 | B59: CSICR_0137 | C59: CSI_0137 | D59: CSI_137 | E59: #N/A | F59: FKRN240343499-1A | G59: 145 | H59: 8.7 | I59: 1.2615 | J59: 9.7 | K59: Pass | L59: Slightly impure | M59: Proceed | O59: Genotyped | P59: INCLUDE | Q59: 2 | R59: 65 | S59: 1 | U59: 1 | W59: EUR | X59: #N/A | Y59: #N/A | AB59: 45397
A60: WAVE-3 | B60: CSICR_0138 | C60: CSI_0138 | D60: CSI_138 | E60: #N/A | F60: FKRN240343500-1A | G60: 108 | H60: 10 | I60: 1.08 | J60: 9.5 | K60: Pass | L60: Slightly impure | M60: Proceed | O60: Genotyped | P60: INCLUDE | Q60: 2 | R60: 63 | S60: 1 | U60: 1 | W60: EUR | X60: #N/A | Y60: #N/A | AB60: 45397
A61: WAVE-3 | B61: CSICR_0142 | C61: CSI_0142 | D61: CSI_142 | E61: #N/A | F61: FKRN240343501-1A | G61: 108 | H61: 9.7 | I61: 1.0476 | J61: 9.4 | K61: Pass | L61: Slightly impure | M61: Proceed | O61: Genotyped | P61: INCLUDE | Q61: 1 | R61: 22 | S61: 1 | U61: 1 | W61: EUR | X61: #N/A | Y61: #N/A | AB61: 45397
... A82: WAVE-3 | B82: GJVR_0199 | C82: GJV_0199 | D82: GJV_199 | E82: #N/A | F82: FKRN240343520-1A | G82: 144 | H82: 8.7 | I82: 1.2528 | J82: 9.6 | K82: Pass | L82: Slightly impure | M82: Proceed | O82: Genotyped | P82: INCLUDE | Q82: 1 | R82: 24 | S82: 1 | U82: 1 | W82: EUR | X82: #N/A | Y82: #N/A | AB82: 45079
A83: WAVE-3 | B83: HGVR_0001 | C83: HGV_0001 | D83: HGV_1 | E83: 45072 | F83: FKRN240343373-1A | G83: 105 | H83: 11 | I83: 1.155 | J83: 9.7 | K83: Pass | L83: - | M83: Proceed | O83: Genotyped | P83: INCLUDE | Q83: 1 | R83: 65 | S83: 2 | T83: BD-II | U83: 1 | W83: EUR | X83: |0| | Y83: |0| | Z83: 7 | AB83: 45205
A84: WAVE-3 | B84: HGVR_0002 | C84: HGV_0002 | D84: HGV_2 | E84: 45072 | F84: FKRN240343374-1A | G84: 130 | H84: 10 | I84: 1.3 | J84: 9.3 | K84: Pass | L84: Slightly impure | M84: Proceed | O84: Genotyped | P84: INCLUDE | Q84: 1 | R84: 38 | S84: 2 | T84: SZaff | U84: 2 | W84: EUR | X84: |0| | Y84: |0| | Z84: 7 | AB84: 45343
A85: WAVE-3 | B85: HGVR_0003 | C85: HGV_0003 | D85: HGV_3 | E85: 45072 | F85: FKRN240343375-1A | G85: 125 | H85: 12 | I85: 1.5 | J85: 9.5 | K85: Pass | L85: - | M85: Proceed | O85: Genotyped | P85: INCLUDE | Q85: 1 | R85: 60 | S85: 2 | T85: BD-II | U85: 1 | W85: EUR | X85: |1| | Y85: |0| | Z85: 7 | AB85: 45343
A86: WAVE-3 | B86: HGVR_0004 | C86: HGV_0004 | D86: HGV_4 | E86: 45072 | F86: FKRN240343376-1A | G86: 132 | H86: 11 | I86: 1.452 | J86: 8.2 | K86: Pass | L86: - | M86: Proceed | O86: Genotyped | P86: INCLUDE | Q86: 1 | R86: 71 | S86: 2 | T86: BD-II | U86: 1 | W86: EUR | X86: |1| | Y86: |0| | Z86: 7 | AB86: 45343
A87: WAVE-3 | B87: HGVR_0005 | C87: HGV_0005 | D87: HGV_5 | E87: 45072 | F87: FKRN240343377-1A | G87: 105 | H87: 9 | I87: 0.945 | J87: 9.5 | K87: Pass | L87: - | M87: Proceed | O87: Genotyped | P87: INCLUDE | Q87: 2 | R87: 40 | S87: 2 | T87: BD-I | U87: 1 | W87: EUR | X87: |1| | Y87: |0| | Z87: 7 | AB87: 45343
A88: WAVE-3 | B88: HGVR_0006 | C88: HGV_0006 | D88: HGV_6 | E88: 45079 | F88: FKRN240343378-1A | G88: 149 | H88: 11 | I88: 1.639 | J88: 9.2 | K88: Pass | L88: Slightly impure | M88: Proceed | O88: Genotyped | P88: INCLUDE | Q88: 2 | R88: 56 | S88: 2 | T88: SZaff | U88: 1 | W88: EUR | X88: |1| | Y88: |0| | Z88: 2 | AB88: 45343
A89: WAVE-3 | B89: HGVR_0007 | C89: HGV_0007 | D89: HGV_7 | E89: 45079 | F89: FKRN240343379-1A | G89: 153 | H89: 12 | I89: 1.836 | J89: 9.7 | K89: Pass | L89: Slightly impure | M89: Proceed | O89: Genotyped | P89: INCLUDE | Q89: 2 | R89: 32 | S89: 2 | T89: SZaff | U89: 1 | W89: EUR | X89: |1| | Y89: |0| | Z89: 7 | AB89: 45343
A90: WAVE-3 | B90: HGVR_0008 | C90: HGV_0008 | D90: HGV_8 | E90: 45079 | F90: FKRN240343380-1A | G90: 130 | H90: 11 | I90: 1.43 | J90: 8.8 | K90: Pass | L90: Slightly impure | M90: Proceed | O90: Genotyped | P90: INCLUDE | Q90: 2 | R90: 66 | S90: 2 | T90: BD-I | U90: 1 | W90: EUR | X90: #N/A | Y90: #N/A | Z90: #N/A | AB90: 45343
A91: WAVE-3 | B91: HGVR_0009 | C91: HGV_0009 | D91: HGV_9 | E91: 45079 | F91: FKRN240343381-1A | G91: 150 | H91: 11 | I91: 1.65 | J91: 9.3 | K91: Pass | L91: Slightly impure | M91: Proceed | O91: Genotyped | P91: INCLUDE | Q91: 2 | R91: 50 | S91: 2 | T91: BD-II | U91: 1 | W91: EUR | X91: |1| | Y91: |0| | Z91: 7 | AB91: 45343
A92: WAVE-3 | B92: HGVR_0010 | C92: HGV_0010 | D92: HGV_10 | E92: 45079 | F92: FKRN240343382-1A | G92: 171 | H92: 11 | I92: 1.881 | J92: 9.5 | K92: Pass | L92: - | M92: Proceed | O92: Genotyped | P92: INCLUDE | Q92: 2 | R92: 54 | S92: 2 | T92: BD-I | U92: 2 | W92: EUR | X92: #N/A | Y92: #N/A | Z92: 7 | AB92: 44473
A93: WAVE-3 | B93: HGVR_0011 | C93: HGV_0011 | D93: HGV_11 | E93: 45083 | F93: FKRN240343383-1A | G93: 96 | H93: 11 | I93: 1.056 | J93: 8.9 | K93: Pass | L93: - | M93: Proceed | O93: Genotyped | P93: INCLUDE | Q93: 2 | R93: 46 | S93: 2 | T93: BD-II | U93: 2 | W93: EUR | X93: #N/A | Y93: #N/A | Z93: 5 | AB93: 44543
A94: WAVE-3 | B94: HGVR_0012 | C94: HGV_0012 | D94: HGV_12 | E94: 45083 | F94: FKRN240343384-1A | G94: 107 | H94: 11 | I94: 1.177 | J94: 9.2 | K94: Pass | L94: Slightly impure | M94: Proceed | O94: Genotyped | P94: INCLUDE | Q94: 2 | R94: 58 | S94: 2 | T94: BD-I | U94: 2 | W94: EUR | X94: |1| | Y94: |0| | Z94: 7 | AB94: 44608
...

Sheet Subjects_excluded_Axiom
A1: Sample | B1: RNAseq | C1: cel_filepath | D1: call_rate | E1: QC computed_sex | F1: cn-probe-chrXY-ratio_sex | G1: Pass/Fail | H1: computed_sex | I1: Clinical sex (reference for .fam) | J1: SNPSEX-PLINK | K1: Concordance Sex Clinical QC-Axiom | L1: Concordance Sex Clinical Plink | M1: Issue if any | N1: Exclusion | O1: Exclusion Reason
A2: CSI_0084 | B2: CSICR_0084 | C2: D:\CEL_files\bd_controles\P23FPGMX083_PL06_050724\CSI_0084.CEL | D2: 99.616 | E2: female | F2: female | G2: Pass | H2: female | I2: female | J2: female | M2: CSIC_83 y CSIC_84 herman@s | N2: exclude | O2: because female and need for > males
A3: SFJ_0137 | B3: SFJR_0137 | C3: D:\CEL_files\suicidas\BacaE_Suicidio_PL03_230424\SFJ_0137.CEL | D3: 99.687 | E3: unknown | F3: unknown | G3: Pass | H3: unknown | I3: male | J3: female | K3: FALSE | L3: FALSE | N3: exclude | O3: sex discrepancy
A4: GJV_0090 | B4: GJVR_0090 | C4: D:\CEL_files\bd_controles\P23FPGMX083_PL07_160724\GJV_0090.CEL | D4: 0 | E4: male | F4: male | G4: Fail | I4: male | J4: #N/A | L4: #N/A | N4: exclude | O4: Qccallrate<0.95
A5: HGV_0024 | B5: HGVR_0024 | C5: D:\CEL_files\bd_controles\P23FPGMX083_PL14_180724\HGV_0024.CEL | D5: 0 | E5: male | F5: male | G5: Fail | I5: male | J5: #N/A | L5: #N/A | N5: exclude | O5: Qccallrate<0.95
A6: HGV_0045 | B6: HGVR_0045 | C6: D:\CEL_files\bd_controles\P23FPGMX083_PL14_180724\HGV_0045.CEL | D6: 98.891 | E6: male | F6: male | G6: Pass | H6: male | I6: male | J6: male | M6: HGV_0045 identical to HGV_0046, pero en teoria son dos hombres no relacionados, excluir porque no sabemos que ha pasado | N6: exclude | O6: HGV_0045 identical to HGV_0046
A7: HGV_0046 | B7: HGVR_0046 | C7: D:\CEL_files\bd_controles\P23FPGMX083_PL14_180724\HGV_0046.CEL | D7: 99.379 | E7: male | F7: male | G7: Pass | H7: male | I7: male | J7: male | M7: HGV_0045 identical to HGV_0046, pero en teoria son dos hombres no relacionados, excluir porque no sabemos que ha pasado | N7: exclude | O7: HGV_0045 identical to HGV_0046
A8: HGV_0048 | B8: HGVR_0048 | C8: D:\CEL_files\bd_controles\P23FPGMX083_PL14_180724\HGV_0048.CEL | D8: 0 | E8: unknown | F8: unknown | G8: Fail | I8: male | J8: #N/A | K8: FALSE | L8: #N/A | N8: exclude | O8: Qccallrate<0.95
A9: HGV_0049 | B9: HGVR_0049 | C9: D:\CEL_files\bd_controles\P23FPGMX083_PL14_180724\HGV_0049.CEL | D9: 0 | E9: unknown | F9: unknown | G9: Fail | I9: female | J9: #N/A | K9: FALSE | L9: #N/A | N9: exclude | O9: Qccallrate<0.95
A10: IEV_0045 | B10: IEVR_0045 | C10: D:\CEL_files\bd_controles\P23FPGMX083_PL12_180724\IEV_0045.CEL | D10: 99.573 | E10: male | F10: male | G10: Pass | H10: male | I10: male | J10: #N/A | L10: #N/A | N10: exclude | O10: F>0.25
A11: IEV_0064 | B11: IEVR_0064 | C11: D:\CEL_files\bd_controles\P23FPGMX083_PL13_180724\IEV_0064.CEL | D11: 99.569 | E11: male | F11: male | G11: Pass | H11: male | I11: male | J11: male | M11: same person IEV_0047 | N11: exclude | O11: < genotyping
A12: PNT_0016 | B12: PNTR_0016 | C12: D:\CEL_files\bd_controles\P23FPGMX083_PL10_170724\PNT_0016.CEL | D12: 99.697 | E12: male | F12: male | G12: Pass | H12: male | I12: male | J12: male | M12: same person PNT_0173 | N12: exclude | O12: < genotyped but RNA reason
A13: PNT_0069 | B13: PNTR_0069 | C13: D:\CEL_files\bd_controles\P23FPGMX083_PL10_170724\PNT_0069.CEL | D13: 0 | E13: male | F13: male | G13: Fail | I13: male | J13: #N/A | L13: #N/A | N13: exclude | O13: Qccallrate<0.95
A14: PNT_0081 | B14: PNTR_0081 | D14: #N/A | I14: #N/A | J14: #N/A | K14: #N/A | L14: #N/A | N14: exclude | O14: cel no generado
A15: PNT_0093 | B15: PNTR_0093 | C15: D:\CEL_files\bd_controles\P23FPGMX083_PL10_170724\PNT_0093.CEL | D15: 99.51 | E15: female | F15: female | G15: Pass | H15: female | I15: female | J15: female | M15: PNT_0093 identical to PNT_0220 | N15: exclude | O15: < genotyping
A16: PNT_0187 | B16: PNTR_0187 | C16: D:\CEL_files\bd_controles\P23FPGMX083_PL11_170724\PNT_0187.CEL | D16: 97.451 | E16: male | F16: male | G16: Fail | I16: male | J16: #N/A | L16: #N/A | N16: exclude | O16: F<-0.1
A17: PNT_0211 | B17: PNTR_0211 | C17: D:\CEL_files\bd_controles\P23FPGMX083_PL12_180724\PNT_0211.CEL | D17: 99.7 | E17: male | F17: male | G17: Pass | H17: male | I17: female | J17: male | K17: FALSE | L17: FALSE | M17: Se procesa con PNT_0210 tb varon. No se puede haber intercambiado, ni hay otra muestra procesada en el mismo dia. No es transexual. Posible error aunque no sabemos que ha pasado. | N17: exclude | O17: sex discrepancy
A18: SFJ_0068 | B18: SFJR_0068 | C18: D:\CEL_files\suicidas\BacaE_Suicidio_PL02_230424\SFJ_0068.CEL | D18: 99.385 | E18: female | F18: female | G18: Pass | H18: female | I18: female | J18: female | M18: PNT_0226 identical to SFJ_0068 | N18: exclude | O18: < genotyping
A19: SFJ_0086 | B19: SFJR_0086 | C19: D:\CEL_files\suicidas\BacaE_Suicidio_PL02_230424\SFJ_0086.CEL | D19: 99.3 | E19: female | F19: female | G19: Pass | H19: female | I19: male | J19: female | K19: FALSE | L19: FALSE | M19: varón en nuestros datos y mujer en QC ==> Excluir | N19: exclude | O19: sex discrepancy
A20: SFJ_0111 | B20: SFJR_0111 | C20: D:\CEL_files\suicidas\BacaE_Suicidio_PL03_230424\SFJ_0111.CEL | D20: 99.2 | E20: male | F20: male | G20: Pass | H20: male | I20: male | J20: male | M20: PNT_0184 identical to SFJ_0111 | N20: exclude | O20: bipolar over suicide
A21: SFJ_0128 | B21: SFJR_0128 | C21: D:\CEL_files\suicidas\BacaE_Suicidio_PL03_230424\SFJ_0128.CEL | D21: 0 | F21: male | G21: Fail | I21: male | J21: #N/A | N21: exclude | O21: DQC<0.82
A22: SFJ_0133 | B22: SFJR_0133 | C22: D:\CEL_files\suicidas\BacaE_Suicidio_PL03_230424\SFJ_0133.CEL | D22: 99.463 | E22: male | F22: male | G22: Pass | H22: male | I22: male | J22: male | M22: PNT_0222 identical to SFJ_0133 | N22: exclude | O22: bipolar over suicide
A23: UAM_0023 | B23: UAMR_0023 | D23: #N/A | I23: #N/A | J23: #N/A | K23: #N/A | L23: #N/A | N23: exclude | O23: cel no generado
A24: UAM_0057 | B24: UAMR_0057 | C24: D:\CEL_files\bd_controles\P23FPGMX083_PL01_030724\UAM_0057.CEL | D24: 96.673 | E24: unknown | F24: unknown | G24: Fail | I24: female | J24: #N/A | K24: FALSE | L24: #N/A | N24: exclude | O24: F<-0.1
A25: UAM_0085 | B25: UAMR_0085 | C25: D:\CEL_files\bd_controles\P23FPGMX083_PL01_030724\UAM_0085.CEL | D25: 0 | E25: unknown | F25: unknown | G25: Fail | I25: female | J25: #N/A | K25: FALSE | L25: #N/A | N25: exclude | O25: Qccallrate<0.95
A26: UAM_0093 | B26: UAMR_0093 | C26: D:\CEL_files\bd_controles\P23FPGMX083_PL01_030724\UAM_0093.CEL | D26: 0 | E26: female | F26: female | G26: Fail | I26: female | J26: #N/A | L26: #N/A | N26: exclude | O26: Qccallrate<0.95
A27: UAM_0178 | B27: UAMR_0178 | C27: D:\CEL_files\bd_controles\P23FPGMX083_PL02_030724\UAM_0178.CEL | D27: 96.626 | E27: unknown | F27: unknown | G27: Fail | I27: male | J27: #N/A | K27: FALSE | L27: #N/A | N27: exclude | O27: F<-0.1
A28: UAM_0179 | B28: UAMR_0179 | C28: D:\CEL_files\bd_controles\P23FPGMX083_PL02_030724\UAM_0179.CEL | D28: 0 | E28: unknown | F28: unknown | G28: Fail | I28: male | J28: #N/A | K28: FALSE | L28: #N/A | N28: exclude | O28: Qccallrate<0.95
A29: UAM_0236 | B29: UAMR_0236 | C29: D:\CEL_files\bd_controles\P23FPGMX083_PL03_040724\UAM_0236.CEL | D29: 99.543 | E29: male | F29: male | G29: Pass | H29: male | I29: male | J29: male | M29: same person UAM_0114 | N29: exclude | O29: same genotypying
A30: UAM_0243 | B30: UAMR_0243 | C30: D:\CEL_files\bd_controles\P23FPGMX083_PL03_040724\UAM_0243.CEL | D30: 99.506 | E30: male | F30: male | G30: Pass | H30: male | I30: #N/A | J30: male | K30: #N/A | L30: #N/A | M30: same person UAM_0453 | N30: exclude | O30: < genotyped of the 2
A31: UAM_0249 | B31: UAMR_0249 | C31: D:\CEL_files\bd_controles\P23FPGMX083_PL03_040724\UAM_0249.CEL | D31: 99.312 | E31: female | F31: female | G31: Pass | H31: female | I31: female | J31: female | M31: same person UAM_0120 | N31: exclude | O31: <genotyping
A32: UAM_0252 | B32: UAMR_0252 | C32: D:\CEL_files\bd_controles\P23FPGMX083_PL03_040724\UAM_0252.CEL | D32: 99.599 | E32: female | F32: female | G32: Pass | H32: female | I32: female | J32: female | M32: UAM_0241 y UAM_0252 parent-child | N32: exclude | O32: younger
A33: UAM_0257 | B33: UAMR_0257 | C33: D:\CEL_files\bd_controles\P23FPGMX083_PL03_040724\UAM_0257.CEL | D33: 0 | E33: unknown | F33: unknown | G33: Fail | I33: male | J33: #N/A | K33: FALSE | L33: #N/A | N33: exclude | O33: Qccallrate<0.95
A34: UAM_0263 | B34: UAMR_0263 | C34: D:\CEL_files\bd_controles\P23FPGMX083_PL03_040724\UAM_0263.CEL | D34: 0 | E34: unknown | F34: unknown | G34: Fail | I34: female | J34: #N/A | K34: FALSE | L34: #N/A | N34: exclude | O34: Qccallrate<0.95
A35: UAM_0284 | B35: UAMR_0284 | C35: D:\CEL_files\bd_controles\P23FPGMX083_PL03_040724\UAM_0284.CEL | D35: 97.867 | E35: female | F35: female | G35: Pass | H35: female | I35: female | J35: #N/A | L35: #N/A | N35: exclude | O35: F<-0.1
A36: UAM_0306 | B36: UAMR_0306 | C36: D:\CEL_files\bd_controles\P23FPGMX083_PL04_040724\UAM_0306.CEL | D36: 99.223 | E36: female | F36: female | G36: Pass | H36: female | I36: female | J36: female | M36: UAM_0305 y UAM_0306 parent-child | N36: exclude | O36: younger
A37: UAM_0310 | B37: UAMR_0310 | C37: D:\CEL_files\bd_controles\P23FPGMX083_PL04_040724\UAM_0310.CEL | D37: 99.536 | E37: female | F37: female | G37: Pass | H37: female | I37: female | J37: female | M37: CSI_0083 y UAM_0310 granparents-half-sib, avuncular | N37: exclude | O37: younger
A38: UAM_0358 | B38: UAMR_0358 | C38: D:\CEL_files\bd_controles\P23FPGMX083_PL04_040724\UAM_0358.CEL | D38: 99.504 | E38: male | F38: male | G38: Pass | H38: male | I38: male | J38: male | M38: UAM_0026 y UAM_0358 parent-child | N38: exclude | O38: young
A39: UAM_0370 | B39: UAMR_0370 | C39: D:\CEL_files\bd_controles\P23FPGMX083_PL04_040724\UAM_0370.CEL | D39: 98.296 | E39: unknown | F39: unknown | G39: Pass | H39: unknown | I39: female | J39: female | K39: FALSE | M39: UAM_0370 same person UAM_0372 | N39: exclude | O39: UAM_0370 identical to UAM_0372, but apparently different people
A40: UAM_0372 | B40: UAMR_0372 | C40: D:\CEL_files\bd_controles\P23FPGMX083_PL04_040724\UAM_0372.CEL | D40: 99.399 | E40: female | F40: female | G40: Pass | H40: female | I40: female | J40: female | M40: UAM_0370 same person UAM_0372 | N40: exclude | O40: UAM_0370 identical to UAM_0372, but apparently different people
...

Sheet Excluded From the study
A1: Wave | B1: Sample Name | C1: Code Axiom | D1: Code Axiom | E1: Nucleic Acid ID | F1: Concentration(ng/ul) | G1: Volume(ul) | H1: Total amount(ug) | I1: Integrity value | J1: Sample QC Results | K1: Sample QC Memo | L1: Recommendation | M1: Note | N1: Genotyping data | O1: Exclude from the study | P1: SEX | Q1: Edad | R1: Aff status BD | S1: BD subtipo | T1: Notas | U1: MDS | V1: Lithium>1yr | W1: Lithium<1yr | X1: Event (LUNKDBECK32) | Y1: Phenotyping date | Z1: Extraction date | AA1: Medicado? (si/no) | AB1: Num medicaciones | AC1: Alguna es mood stabilizer? (si/no)
A2: WAVE-1 | B2: PNTR_0008 | C2: PNT_0008 | D2: PNT_8 | E2: FKRN240109080-1A | F2: 105 | G2: 5 | H2: 0.525 | I2: 9.4 | J2: Pass | K2: - | L2: Proceed | M2: hermanas: PNTR_0008 y PNTR_0023: remove one | N2: Genotyped and excluded (12. PNT_0008 y PNT_0023 herman@s) | O2: Exclude | P2: #N/A | Q2: #N/A | R2: #N/A | S2: BD-II | U2: EUR | V2: #N/A | W2: #N/A | X2: #N/A | Y2: #N/A | Z2: 44693
A3: WAVE-1 | B3: PNTR_0093 | C3: PNT_0093 | D3: PNT_93 | E3: FKRN240109236-1A | F3: 144 | G3: 6.9 | H3: 0.9936 | I3: 9.2 | J3: Pass | K3: - | L3: Proceed | M3: (duplicated PNTR_0220) | N3: Genotyped and excluded (7: IBD (duplicated) | O3: Exclude | P3: #N/A | Q3: #N/A | R3: #N/A | S3: BD-I | U3: #N/A | V3: |1| | W3: |0| | X3: 7 | Y3: 24/11/2022 | Z3: 44868
A4: WAVE-2 | B4: UAMR_0252 | C4: UAM_0252 | D4: UAM_252 | E4: FKRN240159893-1A | F4: 103 | G4: 8.7 | H4: 0.8961 | I4: 9.8 | J4: Pass | K4: - | L4: Proceed | M4: UAM_0241 (padre) y UAM_0252 (hija) parent-child | N4: Genotyped and excluded (UAM_0241 y UAM_0252 parent-child) | O4: Exclude | P4: #N/A | Q4: #N/A | R4: #N/A | U4: #N/A | V4: #N/A | W4: #N/A | Z4: 44853

Sheet config_file_DEGs
A1: Sample_name | B1: File | C1: Age_range | D1: Sex | E1: Case_Ctrl_BD | F1: Case_Ctrl_SA | G1: PC1_CIBERSORT | H1: PC2_CIBERSORT | I1: PC3_CIBERSORT | J1: PC4_CIBERSORT | K1: PC5_CIBERSORT | L1: Wave | M1: RIN | N1: Ethnicity | O1: Subtype | P1: Age
A2: CSI_0001 | B2: CSICR_0001.tsv | C2: group_51_to_60 | D2: Female | E2: Control | F2: Control | G2: 0.15715068 | H2: 2.748833 | I2: -0.40035454 | J2: -0.45381356 | K2: -0.87496018 | L2: WAVE-3 | M2: 9.8 | N2: EUR | O2: Control | P2: =VLOOKUP(A2,Whole_Data_RNAseq!C:R,16,FALSE) -> 55
A3: CSI_0008 | B3: CSICR_0008.tsv | C3: group_51_to_60 | D3: Female | E3: Control | F3: Control | G3: 4.632077 | H3: -0.99175562 | I3: -0.15914753 | J3: 1.5985452 | K3: 0.34014223 | L3: WAVE-2 | M3: 8.6 | N3: EUR | O3: Control | P3: =VLOOKUP(A3,Whole_Data_RNAseq!C:R,16,FALSE) -> 51
A4: CSI_0011 | B4: CSICR_0011.tsv | C4: group_41_to_50 | D4: Male | E4: Control | F4: Control | G4: 0.65583307 | H4: -1.7183559 | I4: -0.030355326 | J4: 0.50604003 | K4: -1.6751643 | L4: WAVE-2 | M4: 9 | N4: EUR | O4: Control | P4: =VLOOKUP(A4,Whole_Data_RNAseq!C:R,16,FALSE) -> 46
A5: CSI_0012 | B5: CSICR_0012.tsv | C5: group_51_to_60 | D5: Male | E5: Control | F5: Control | G5: -2.2426664 | H5: -0.39449688 | I5: 1.5508624 | J5: 0.81274323 | K5: 1.3483866 | L5: WAVE-3 | M5: 9.8 | N5: EUR | O5: Control | P5: =VLOOKUP(A5,Whole_Data_RNAseq!C:R,16,FALSE) -> 57
A6: CSI_0013 | B6: CSICR_0013.tsv | C6: group_41_to_50 | D6: Female | E6: Control | F6: Control | G6: -0.50917603 | H6: 0.94586815 | I6: -0.48347963 | J6: 1.0910233 | K6: 0.96748179 | L6: WAVE-R | M6: 9.8 | N6: EUR | O6: Control | P6: =VLOOKUP(A6,Whole_Data_RNAseq!C:R,16,FALSE) -> 48
A7: CSI_0015 | B7: CSICR_0015.tsv | C7: group_51_to_60 | D7: Female | E7: Control | F7: Control | G7: 0.029682566 | H7: 0.42435405 | I7: -0.24385758 | J7: 0.19459791 | K7: -0.53129225 | L7: WAVE-R | M7: 9 | N7: EUR | O7: Control | P7: =VLOOKUP(A7,Whole_Data_RNAseq!C:R,16,FALSE) -> 57
A8: CSI_0017 | B8: CSICR_0017.tsv | C8: group_51_to_60 | D8: Female | E8: Control | F8: Control | G8: -0.35070719 | H8: -1.0654755 | I8: -0.7256419 | J8: 0.016802401 | K8: 0.49305546 | L8: WAVE-3 | M8: 9.8 | N8: EUR | O8: Control | P8: =VLOOKUP(A8,Whole_Data_RNAseq!C:R,16,FALSE) -> 53
A9: CSI_0018 | B9: CSICR_0018.tsv | C9: group_51_to_60 | D9: Female | E9: Control | F9: Control | G9: 3.0528494 | H9: -0.64505647 | I9: -0.083076813 | J9: 1.3185026 | K9: 0.99971158 | L9: WAVE-3 | M9: 9.6 | N9: EUR | O9: Control | P9: =VLOOKUP(A9,Whole_Data_RNAseq!C:R,16,FALSE) -> 59
A10: CSI_0026 | B10: CSICR_0026.tsv | C10: group_61_to_70 | D10: Female | E10: Control | F10: Control | G10: 1.5931264 | H10: 2.1130313 | I10: 1.08017 | J10: 0.97448731 | K10: -2.2839088 | L10: WAVE-2 | M10: 9.4 | N10: EUR | O10: Control | P10: =VLOOKUP(A10,Whole_Data_RNAseq!C:R,16,FALSE) -> 63
A11: CSI_0030 | B11: CSICR_0030.tsv | C11: group_41_to_50 | D11: Female | E11: Control | F11: Control | G11: 0.29859915 | H11: 0.23139289 | I11: -0.16954939 | J11: 0.11007941 | K11: 1.0374281 | L11: WAVE-2 | M11: 9.2 | N11: EUR | O11: Control | P11: =VLOOKUP(A11,Whole_Data_RNAseq!C:R,16,FALSE) -> 49
A12: CSI_0031 | B12: CSICR_0031.tsv | C12: group_41_to_50 | D12: Male | E12: Control | F12: Control | G12: -0.81077691 | H12: 0.12715463 | I12: 0.04088051 | J12: -0.42458274 | K12: 0.67374618 | L12: WAVE-2 | M12: 9.5 | N12: EUR | O12: Control | P12: =VLOOKUP(A12,Whole_Data_RNAseq!C:R,16,FALSE) -> 50
A13: CSI_0033 | B13: CSICR_0033.tsv | C13: group_61_to_70 | D13: Female | E13: Control | F13: Control | G13: -3.099378 | H13: 0.9443083 | I13: 1.2660242 | J13: 0.64967275 | K13: 1.554436 | L13: WAVE-1 | M13: 9.8 | N13: EUR | O13: Control | P13: =VLOOKUP(A13,Whole_Data_RNAseq!C:R,16,FALSE) -> 63
... A723: UAM_0390 | B723: UAMR_0390.tsv | C723: group_under_30 | D723: Female | E723: Control | F723: Control | G723: 0.45880985 | H723: -1.16867 | I723: -1.2006777 | J723: -1.3827423 | K723: 1.9661565 | L723: WAVE-3 | M723: 9.8 | N723: No_EUR | O723: Control | P723: =VLOOKUP(A723,Whole_Data_RNAseq!C:R,16,FALSE) -> 23
